<?xml version="1.0" ?>
<!-- =================================================================================== -->
<!-- |    This document was autogenerated by xacro from /home/felixwidmaier/ws/fingers/workspace/src/catkin/robots/robot_properties/robot_properties_fingers/xacro/trifinger.urdf.xacro | -->
<!-- |    EDITING THIS FILE BY HAND IS NOT RECOMMENDED                                 | -->
<!-- =================================================================================== -->
<robot name="finger_with_stage" xmlns:xacro="https://ei.is.tuebingen.mpg.de/xacro">
  <!--
    Frames are defined such that they all align with the base frame when all
    joints are at position zero.

    In zero-configuration the origins of all joints are in one line.

    In zero-configuration the origin of the base link is exactly above the
    finger tip which should make it easy to place the finger in the world.
    -->
  <!-- Define the global base_link and place all other objects relative to it. -->
  <link name="base_link">
    <inertial>
      <origin rpy="0 0 0" xyz="0 0 0"/>
      <mass value="1"/>
      <inertia ixx="4.16666666667e-06" ixy="0" ixz="0" iyy="4.16666666667e-06" iyz="0" izz="4.16666666667e-06"/>
    </inertial>
  </link>
  <!-- Define the upper holder -->
  <link name="upper_holder_link">
    <inertial>
      <mass value="0"/>
      <inertia ixx="0.0" ixy="0.0" ixz="0.0" iyy="0.0" iyz="0.0" izz="0.0"/>
    </inertial>
  </link>
  <joint name="base_to_upper_holder_joint" type="fixed">
    <parent link="base_link"/>
    <child link="upper_holder_link"/>
    <origin xyz="0 0 0.34"/>
  </joint>
  <material name="finger_0_material">
    <color rgba="0.6 0.0 0.0 1.0"/>
  </material>
  <material name="finger_120_material">
    <color rgba="0.0 0.6 0.0 1.0"/>
  </material>
  <material name="finger_240_material">
    <color rgba="0.0 0.0 0.6 1.0"/>
  </material>
  <!--
        Fixed links for the finger base (parts where the upper link is mounted).
        -->
  <link name="finger_base_link_0">
    <visual>
      <origin rpy="0 0 0" xyz="0 0.179 0"/>
      <geometry>
        <mesh filename="package://robot_properties_fingers/meshes/stl/SIM__BL-Finger_Base.stl" scale="1 1 1"/>
      </geometry>
      <material name="finger_0_material"/>
    </visual>
    <collision>
      <origin rpy="0 0 0" xyz="0 0.179 0"/>
      <geometry>
        <mesh filename="package://robot_properties_fingers/meshes/stl/SIM__BL-Finger_Base.stl" scale="1 1 1"/>
      </geometry>
    </collision>
    <inertial>
      <origin rpy="0 0 0" xyz="0 0 0"/>
      <mass value="1"/>
      <inertia ixx="0.000416666666667" ixy="0" ixz="0" iyy="0.000416666666667" iyz="0" izz="0.000416666666667"/>
    </inertial>
  </link>
  <!-- The movable links (upper, middle and lower) of the finger. -->
  <!-- TODO inertia parameters don't look correct, they cant be same for upper and middle! -->
  <link name="finger_upper_link_0">
    <visual>
      <origin rpy="0 0 0" xyz="0 -0.02695 0"/>
      <geometry>
        <mesh filename="package://robot_properties_fingers/meshes/stl/SIM__BL-Finger_Proximal.stl" scale="1 1 1"/>
      </geometry>
      <material name="finger_0_material"/>
    </visual>
    <collision>
      <origin rpy="0 0 0" xyz="0 -0.02695 0"/>
      <geometry>
        <mesh filename="package://robot_properties_fingers/meshes/stl/SIM__BL-Finger_Proximal.stl" scale="1 1 1"/>
      </geometry>
    </collision>
    <inertial>
      <origin rpy="0 0 0" xyz="0 0.06 0"/>
      <mass value="0.2"/>
      <inertia ixx="0.000353333333333" ixy="0" ixz="0" iyy="5.33333333333e-05" iyz="0" izz="0.000353333333333"/>
    </inertial>
  </link>
  <link name="finger_middle_link_0">
    <visual>
      <origin rpy="1.57079632679 0 0" xyz="0.014 0 0"/>
      <geometry>
        <mesh filename="package://robot_properties_fingers/meshes/stl/SIM__BL-Finger_Intermediate.stl" scale="1 1 1"/>
      </geometry>
      <material name="finger_0_material"/>
    </visual>
    <collision>
      <origin rpy="1.57079632679 0 0" xyz="0.014 0 0"/>
      <geometry>
        <mesh filename="package://robot_properties_fingers/meshes/stl/SIM__BL-Finger_Intermediate.stl" scale="1 1 1"/>
      </geometry>
    </collision>
    <inertial>
      <origin rpy="0 0 0" xyz="0.028 0 -0.08"/>
      <mass value="0.2"/>
      <inertia ixx="0.000353333333333" ixy="0" ixz="0" iyy="0.000353333333333" iyz="0" izz="5.33333333333e-05"/>
    </inertial>
  </link>
  <link name="finger_lower_link_0">
    <visual>
      <origin rpy="1.57079632679 0 0" xyz="0.014 0 0"/>
      <geometry>
        <mesh filename="package://robot_properties_fingers/meshes/stl/SIM_BL_FINGER_TIP_LINK.stl" scale="1 1 1"/>
      </geometry>
      <material name="finger_0_material"/>
    </visual>
    <collision>
      <origin rpy="1.57079632679 0 0" xyz="0.014 0 0"/>
      <geometry>
        <mesh filename="package://robot_properties_fingers/meshes/stl/SIM_BL_FINGER_TIP_LINK.stl" scale="1 1 1"/>
      </geometry>
    </collision>
    <inertial>
      <origin rpy="0 0 0" xyz="0 0 -0.06"/>
      <mass value="0.01"/>
      <inertia ixx="1.66666666667e-05" ixy="0" ixz="0" iyy="1.66666666667e-05" iyz="0" izz="6.66666666667e-07"/>
    </inertial>
  </link>
  <!-- fixed link for finger tip -->
  <link name="finger_tip_link_0">
    <inertial>
      <origin rpy="0 0 0" xyz="0 0 0"/>
      <mass value="0.02"/>
      <inertia ixx="3.33333333333e-07" ixy="0" ixz="0" iyy="3.33333333333e-07" iyz="0" izz="3.33333333333e-07"/>
    </inertial>
  </link>
  <joint name="finger_lower_to_tip_joint_0" type="fixed">
    <parent link="finger_lower_link_0"/>
    <child link="finger_tip_link_0"/>
    <origin xyz="0 0 -0.16"/>
  </joint>
  <!-- kinematics -->
  <!-- TODO: joint limits are based on values from wiki
        (https://atlas.is.localnet/confluence/display/AMDW/Forward+Kinematics) but
        should be verified on the real system (especially the finger tip limits look
        a bit too big when visualizing the model. -->
  <joint name="finger_base_to_upper_joint_0" type="revolute">
    <parent link="finger_base_link_0"/>
    <child link="finger_upper_link_0"/>
    <limit effort="1000" lower="-1.57079632679" upper="1.57079632679" velocity="1000"/>
    <axis xyz="0 1 0"/>
    <origin rpy="0 0 0" xyz="0 0 0"/>
  </joint>
  <joint name="finger_upper_to_middle_joint_0" type="revolute">
    <parent link="finger_upper_link_0"/>
    <child link="finger_middle_link_0"/>
    <limit effort="1000" lower="-1.3526301703" upper="4.49422282389" velocity="1000"/>
    <axis xyz="-1 0 0"/>
    <origin rpy="0 0 0" xyz="0 0 0"/>
  </joint>
  <joint name="finger_middle_to_lower_joint_0" type="revolute">
    <parent link="finger_middle_link_0"/>
    <child link="finger_lower_link_0"/>
    <!-- <limit effort="1000" lower="${radians(-172)}" upper="${radians(172)}" velocity="1000"/> -->
    <limit effort="1000" lower="-3.00196631343" upper="-0.0349065850399" velocity="1000"/>
    <axis xyz="1 0 0"/>
    <origin rpy="0 0 0" xyz="0 0 -0.16"/>
  </joint>
  <!--
        Fixed links for the finger base (parts where the upper link is mounted).
        -->
  <link name="finger_base_link_120">
    <visual>
      <origin rpy="0 0 0" xyz="0 0.179 0"/>
      <geometry>
        <mesh filename="package://robot_properties_fingers/meshes/stl/SIM__BL-Finger_Base.stl" scale="1 1 1"/>
      </geometry>
      <material name="finger_120_material"/>
    </visual>
    <collision>
      <origin rpy="0 0 0" xyz="0 0.179 0"/>
      <geometry>
        <mesh filename="package://robot_properties_fingers/meshes/stl/SIM__BL-Finger_Base.stl" scale="1 1 1"/>
      </geometry>
    </collision>
    <inertial>
      <origin rpy="0 0 0" xyz="0 0 0"/>
      <mass value="1"/>
      <inertia ixx="0.000416666666667" ixy="0" ixz="0" iyy="0.000416666666667" iyz="0" izz="0.000416666666667"/>
    </inertial>
  </link>
  <!-- The movable links (upper, middle and lower) of the finger. -->
  <!-- TODO inertia parameters don't look correct, they cant be same for upper and middle! -->
  <link name="finger_upper_link_120">
    <visual>
      <origin rpy="0 0 0" xyz="0 -0.02695 0"/>
      <geometry>
        <mesh filename="package://robot_properties_fingers/meshes/stl/SIM__BL-Finger_Proximal.stl" scale="1 1 1"/>
      </geometry>
      <material name="finger_120_material"/>
    </visual>
    <collision>
      <origin rpy="0 0 0" xyz="0 -0.02695 0"/>
      <geometry>
        <mesh filename="package://robot_properties_fingers/meshes/stl/SIM__BL-Finger_Proximal.stl" scale="1 1 1"/>
      </geometry>
    </collision>
    <inertial>
      <origin rpy="0 0 0" xyz="0 0.06 0"/>
      <mass value="0.2"/>
      <inertia ixx="0.000353333333333" ixy="0" ixz="0" iyy="5.33333333333e-05" iyz="0" izz="0.000353333333333"/>
    </inertial>
  </link>
  <link name="finger_middle_link_120">
    <visual>
      <origin rpy="1.57079632679 0 0" xyz="0.014 0 0"/>
      <geometry>
        <mesh filename="package://robot_properties_fingers/meshes/stl/SIM__BL-Finger_Intermediate.stl" scale="1 1 1"/>
      </geometry>
      <material name="finger_120_material"/>
    </visual>
    <collision>
      <origin rpy="1.57079632679 0 0" xyz="0.014 0 0"/>
      <geometry>
        <mesh filename="package://robot_properties_fingers/meshes/stl/SIM__BL-Finger_Intermediate.stl" scale="1 1 1"/>
      </geometry>
    </collision>
    <inertial>
      <origin rpy="0 0 0" xyz="0.028 0 -0.08"/>
      <mass value="0.2"/>
      <inertia ixx="0.000353333333333" ixy="0" ixz="0" iyy="0.000353333333333" iyz="0" izz="5.33333333333e-05"/>
    </inertial>
  </link>
  <link name="finger_lower_link_120">
    <visual>
      <origin rpy="1.57079632679 0 0" xyz="0.014 0 0"/>
      <geometry>
        <mesh filename="package://robot_properties_fingers/meshes/stl/SIM_BL_FINGER_TIP_LINK.stl" scale="1 1 1"/>
      </geometry>
      <material name="finger_120_material"/>
    </visual>
    <collision>
      <origin rpy="1.57079632679 0 0" xyz="0.014 0 0"/>
      <geometry>
        <mesh filename="package://robot_properties_fingers/meshes/stl/SIM_BL_FINGER_TIP_LINK.stl" scale="1 1 1"/>
      </geometry>
    </collision>
    <inertial>
      <origin rpy="0 0 0" xyz="0 0 -0.06"/>
      <mass value="0.01"/>
      <inertia ixx="1.66666666667e-05" ixy="0" ixz="0" iyy="1.66666666667e-05" iyz="0" izz="6.66666666667e-07"/>
    </inertial>
  </link>
  <!-- fixed link for finger tip -->
  <link name="finger_tip_link_120">
    <inertial>
      <origin rpy="0 0 0" xyz="0 0 0"/>
      <mass value="0.02"/>
      <inertia ixx="3.33333333333e-07" ixy="0" ixz="0" iyy="3.33333333333e-07" iyz="0" izz="3.33333333333e-07"/>
    </inertial>
  </link>
  <joint name="finger_lower_to_tip_joint_120" type="fixed">
    <parent link="finger_lower_link_120"/>
    <child link="finger_tip_link_120"/>
    <origin xyz="0 0 -0.16"/>
  </joint>
  <!-- kinematics -->
  <!-- TODO: joint limits are based on values from wiki
        (https://atlas.is.localnet/confluence/display/AMDW/Forward+Kinematics) but
        should be verified on the real system (especially the finger tip limits look
        a bit too big when visualizing the model. -->
  <joint name="finger_base_to_upper_joint_120" type="revolute">
    <parent link="finger_base_link_120"/>
    <child link="finger_upper_link_120"/>
    <limit effort="1000" lower="-1.57079632679" upper="1.57079632679" velocity="1000"/>
    <axis xyz="0 1 0"/>
    <origin rpy="0 0 0" xyz="0 0 0"/>
  </joint>
  <joint name="finger_upper_to_middle_joint_120" type="revolute">
    <parent link="finger_upper_link_120"/>
    <child link="finger_middle_link_120"/>
    <limit effort="1000" lower="-1.3526301703" upper="4.49422282389" velocity="1000"/>
    <axis xyz="-1 0 0"/>
    <origin rpy="0 0 0" xyz="0 0 0"/>
  </joint>
  <joint name="finger_middle_to_lower_joint_120" type="revolute">
    <parent link="finger_middle_link_120"/>
    <child link="finger_lower_link_120"/>
    <!-- <limit effort="1000" lower="${radians(-172)}" upper="${radians(172)}" velocity="1000"/> -->
    <limit effort="1000" lower="-3.00196631343" upper="-0.0349065850399" velocity="1000"/>
    <axis xyz="1 0 0"/>
    <origin rpy="0 0 0" xyz="0 0 -0.16"/>
  </joint>
  <!--
        Fixed links for the finger base (parts where the upper link is mounted).
        -->
  <link name="finger_base_link_240">
    <visual>
      <origin rpy="0 0 0" xyz="0 0.179 0"/>
      <geometry>
        <mesh filename="package://robot_properties_fingers/meshes/stl/SIM__BL-Finger_Base.stl" scale="1 1 1"/>
      </geometry>
      <material name="finger_240_material"/>
    </visual>
    <collision>
      <origin rpy="0 0 0" xyz="0 0.179 0"/>
      <geometry>
        <mesh filename="package://robot_properties_fingers/meshes/stl/SIM__BL-Finger_Base.stl" scale="1 1 1"/>
      </geometry>
    </collision>
    <inertial>
      <origin rpy="0 0 0" xyz="0 0 0"/>
      <mass value="1"/>
      <inertia ixx="0.000416666666667" ixy="0" ixz="0" iyy="0.000416666666667" iyz="0" izz="0.000416666666667"/>
    </inertial>
  </link>
  <!-- The movable links (upper, middle and lower) of the finger. -->
  <!-- TODO inertia parameters don't look correct, they cant be same for upper and middle! -->
  <link name="finger_upper_link_240">
    <visual>
      <origin rpy="0 0 0" xyz="0 -0.02695 0"/>
      <geometry>
        <mesh filename="package://robot_properties_fingers/meshes/stl/SIM__BL-Finger_Proximal.stl" scale="1 1 1"/>
      </geometry>
      <material name="finger_240_material"/>
    </visual>
    <collision>
      <origin rpy="0 0 0" xyz="0 -0.02695 0"/>
      <geometry>
        <mesh filename="package://robot_properties_fingers/meshes/stl/SIM__BL-Finger_Proximal.stl" scale="1 1 1"/>
      </geometry>
    </collision>
    <inertial>
      <origin rpy="0 0 0" xyz="0 0.06 0"/>
      <mass value="0.2"/>
      <inertia ixx="0.000353333333333" ixy="0" ixz="0" iyy="5.33333333333e-05" iyz="0" izz="0.000353333333333"/>
    </inertial>
  </link>
  <link name="finger_middle_link_240">
    <visual>
      <origin rpy="1.57079632679 0 0" xyz="0.014 0 0"/>
      <geometry>
        <mesh filename="package://robot_properties_fingers/meshes/stl/SIM__BL-Finger_Intermediate.stl" scale="1 1 1"/>
      </geometry>
      <material name="finger_240_material"/>
    </visual>
    <collision>
      <origin rpy="1.57079632679 0 0" xyz="0.014 0 0"/>
      <geometry>
        <mesh filename="package://robot_properties_fingers/meshes/stl/SIM__BL-Finger_Intermediate.stl" scale="1 1 1"/>
      </geometry>
    </collision>
    <inertial>
      <origin rpy="0 0 0" xyz="0.028 0 -0.08"/>
      <mass value="0.2"/>
      <inertia ixx="0.000353333333333" ixy="0" ixz="0" iyy="0.000353333333333" iyz="0" izz="5.33333333333e-05"/>
    </inertial>
  </link>
  <link name="finger_lower_link_240">
    <visual>
      <origin rpy="1.57079632679 0 0" xyz="0.014 0 0"/>
      <geometry>
        <mesh filename="package://robot_properties_fingers/meshes/stl/SIM_BL_FINGER_TIP_LINK.stl" scale="1 1 1"/>
      </geometry>
      <material name="finger_240_material"/>
    </visual>
    <collision>
      <origin rpy="1.57079632679 0 0" xyz="0.014 0 0"/>
      <geometry>
        <mesh filename="package://robot_properties_fingers/meshes/stl/SIM_BL_FINGER_TIP_LINK.stl" scale="1 1 1"/>
      </geometry>
    </collision>
    <inertial>
      <origin rpy="0 0 0" xyz="0 0 -0.06"/>
      <mass value="0.01"/>
      <inertia ixx="1.66666666667e-05" ixy="0" ixz="0" iyy="1.66666666667e-05" iyz="0" izz="6.66666666667e-07"/>
    </inertial>
  </link>
  <!-- fixed link for finger tip -->
  <link name="finger_tip_link_240">
    <inertial>
      <origin rpy="0 0 0" xyz="0 0 0"/>
      <mass value="0.02"/>
      <inertia ixx="3.33333333333e-07" ixy="0" ixz="0" iyy="3.33333333333e-07" iyz="0" izz="3.33333333333e-07"/>
    </inertial>
  </link>
  <joint name="finger_lower_to_tip_joint_240" type="fixed">
    <parent link="finger_lower_link_240"/>
    <child link="finger_tip_link_240"/>
    <origin xyz="0 0 -0.16"/>
  </joint>
  <!-- kinematics -->
  <!-- TODO: joint limits are based on values from wiki
        (https://atlas.is.localnet/confluence/display/AMDW/Forward+Kinematics) but
        should be verified on the real system (especially the finger tip limits look
        a bit too big when visualizing the model. -->
  <joint name="finger_base_to_upper_joint_240" type="revolute">
    <parent link="finger_base_link_240"/>
    <child link="finger_upper_link_240"/>
    <limit effort="1000" lower="-1.57079632679" upper="1.57079632679" velocity="1000"/>
    <axis xyz="0 1 0"/>
    <origin rpy="0 0 0" xyz="0 0 0"/>
  </joint>
  <joint name="finger_upper_to_middle_joint_240" type="revolute">
    <parent link="finger_upper_link_240"/>
    <child link="finger_middle_link_240"/>
    <limit effort="1000" lower="-1.3526301703" upper="4.49422282389" velocity="1000"/>
    <axis xyz="-1 0 0"/>
    <origin rpy="0 0 0" xyz="0 0 0"/>
  </joint>
  <joint name="finger_middle_to_lower_joint_240" type="revolute">
    <parent link="finger_middle_link_240"/>
    <child link="finger_lower_link_240"/>
    <!-- <limit effort="1000" lower="${radians(-172)}" upper="${radians(172)}" velocity="1000"/> -->
    <limit effort="1000" lower="-3.00196631343" upper="-0.0349065850399" velocity="1000"/>
    <axis xyz="1 0 0"/>
    <origin rpy="0 0 0" xyz="0 0 -0.16"/>
  </joint>
  <joint name="holder_to_finger_0" type="fixed">
    <parent link="upper_holder_link"/>
    <child link="finger_base_link_0"/>
    <origin rpy="0 0 0" xyz="0.0 0.04 0"/>
  </joint>
  <joint name="holder_to_finger_120" type="fixed">
    <parent link="upper_holder_link"/>
    <child link="finger_base_link_120"/>
    <origin rpy="0 0 -2.09439510239" xyz="0.0346410161514 -0.02 0"/>
  </joint>
  <joint name="holder_to_finger_240" type="fixed">
    <parent link="upper_holder_link"/>
    <child link="finger_base_link_240"/>
    <origin rpy="0 0 -4.18879020479" xyz="-0.0346410161514 -0.02 0"/>
  </joint>
</robot>
